Workbook
Name a: correcoes!$C$63
Name alfa: correcoes!$J$64
Name b: correcoes!$C$64
Name d: Analise_tempo!$E$2
Name kb: correcoes!$C$69
Name T: correcoes!$C$70
Name time: correcoes!$J$66

Sheet input
M1: Acompanhar pico de N2+, que só deve começar a cair DEPOIS de 3000ns
E2: Data | F2: 41220 | M2: para comparação o t(ns) medido deve ser acrecido de 400ns!!!!
E3: Gás | F3: O2 | H3: Keithley escala ,3
E4: Operadores | F4: Lucas^2
F6: MEDIDA CORRENTE | H6: MEDIDA PRESSÃO
A7: no osciloscópio | D7: Sem Feixe | H7: BARATRON (mTorr) | K7: x 10 ^ -6 Torr | N7: extra | O7: Observações
B8: tempo(ns) | C8: medida | D8: t (s) | E8: # i | F8: t (s) | G8: # i | H8: pi(mTorr) | I8: pf(mTorr) | J8: fundo | K8: pi_penning | L8: pf_penning | M8: fundo penning | N8: p_linha
A9: =B9+600 -> 600 | B9: 0 | C9: 1 | D9: 20 | E9: 8359 | F9: 200 | G9: 268328 | H9: 1.48 | I9: 1.48 | J9: 1.16 | K9: 1.42 | L9: 1.43 | M9: 0.76 | N9: 269
A10: =B10+600 -> 600 | B10: 0 | C10: 2 | D10: 20 | E10: 8380 | F10: 200 | G10: 339451 | H10: 1.48 | I10: 1.48 | J10: 1.16 | K10: 1.44 | L10: 1.44 | M10: 0.76 | N10: 273
A11: =B11+600 -> 700 | B11: 100 | C11: 3 | D11: 20 | E11: 8132 | F11: 200 | G11: 244483 | H11: 1.49 | I11: 1.49 | J11: 1.16 | K11: 1.44 | L11: 1.45 | M11: 0.76 | N11: 275
A12: =B12+600 -> 700 | B12: 100 | C12: 4 | D12: 20 | E12: 8118 | F12: 200 | G12: 271876 | H12: 1.49 | I12: 1.49 | J12: 1.16 | K12: 1.45 | L12: 1.45 | M12: 0.76 | N12: 276
A13: =B13+600 -> 800 | B13: 200 | C13: 5 | D13: 20 | E13: 8135 | F13: 200 | G13: 307177 | H13: 1.49 | I13: 1.49 | J13: 1.16 | K13: 1.45 | L13: 1.46 | M13: 0.76 | N13: 276
A14: =B14+600 -> 800 | B14: 200 | C14: 6 | D14: 20 | E14: 8171 | F14: 200 | G14: 253503 | H14: 1.49 | I14: 1.49 | J14: 1.16 | K14: 1.46 | L14: 1.46 | M14: 0.76 | N14: 274 | O14: ruído "fantasma"
A15: =B15+600 -> 900 | B15: 300 | C15: 7 | D15: 20 | E15: 8119 | F15: 200 | G15: 250327 | H15: 1.49 | I15: 1.49 | J15: 1.16 | K15: 1.46 | L15: 1.46 | M15: 0.76 | N15: 276
A16: =B16+600 -> 900 | B16: 300 | C16: 8 | D16: 20 | E16: 8135 | F16: 200 | G16: 254408 | H16: 1.49 | I16: 1.49 | J16: 1.16 | K16: 1.47 | L16: 1.47 | M16: 0.76 | N16: 277
A17: =B17+600 -> 1000 | B17: 400 | C17: 9 | D17: 20 | E17: 8115 | F17: 200 | G17: 264086 | H17: 1.49 | I17: 1.49 | J17: 1.16 | K17: 1.47 | L17: 1.47 | M17: 0.76 | N17: 279
A18: =B18+600 -> 1000 | B18: 400 | C18: 10 | D18: 20 | E18: 8262 | F18: 200 | G18: 255708 | H18: 1.49 | I18: 1.49 | J18: 1.16 | K18: 1.48 | L18: 1.48 | M18: 0.76 | N18: 280
A19: =B19+600 -> 1100 | B19: 500 | C19: 11 | D19: 20 | E19: 8350 | F19: 200 | G19: 278293 | H19: 1.48 | I19: 1.48 | J19: 1.16 | K19: 1.48 | L19: 1.48 | M19: 0.76 | N19: 281
A20: =B20+600 -> 1100 | B20: 500 | C20: 12 | D20: 20 | E20: 8269 | F20: 200 | G20: 274263 | H20: 1.48 | I20: 1.48 | J20: 1.16 | K20: 1.5 | L20: 1.5 | M20: 0.76 | N20: 282
A21: =B21+600 -> 1200 | B21: 600 | C21: 13 | D21: 20 | E21: 8323 | F21: 200 | G21: 305036 | H21: 1.48 | I21: 1.48 | J21: 1.16 | K21: 1.5 | L21: 1.5 | M21: 0.76 | N21: 283
A22: =B22+600 -> 1200 | B22: 600 | C22: 14 | D22: 20 | E22: 8311 | F22: 200 | G22: 315832 | H22: 1.48 | I22: 1.48 | J22: 1.16 | K22: 1.5 | L22: 1.5 | M22: 0.76 | N22: 283
A23: =B23+600 -> 1400 | B23: 800 | C23: 15 | D23: 20 | E23: 8336 | F23: 200 | G23: 334516 | H23: 1.48 | I23: 1.47 | J23: 1.16 | K23: 1.5 | L23: 1.5 | M23: 0.76 | N23: 284
A24: =B24+600 -> 1400 | B24: 800 | C24: 16 | D24: 20 | E24: 8286 | F24: 200 | G24: 294219 | H24: 1.47 | I24: 1.48 | J24: 1.16 | K24: 1.5 | L24: 1.5 | M24: 0.76 | N24: 285
A25: =B25+600 -> 600 | B25: 0 | C25: 17 | D25: 20 | E25: 8322 | F25: 200 | G25: 282618 | H25: 1.48 | I25: 1.48 | J25: 1.16 | K25: 1.5 | L25: 1.5 | M25: 0.76 | N25: 284
A26: =B26+600 -> 600 | B26: 0 | C26: 18 | D26: 20 | E26: 8338 | F26: 200 | G26: 266535 | H26: 1.48 | I26: 1.48 | J26: 1.16 | K26: 1.5 | L26: 1.5 | M26: 0.76 | N26: 283
... A60: =B60+600 -> 600 | B60: 0 | C60: 52 | D60: 20 | E60: 8220 | F60: 200 | G60: 411764 | H60: 1.49 | I60: 1.49 | J60: 1.16 | K60: 1.52 | L60: 1.52 | M60: 0.76 | N60: 285
A61: =B61+600 -> 600 | B61: 0 | C61: 53 | D61: 20 | F61: 200 | J61: 1.16 | M61: 0.76
A62: =B62+600 -> 600 | B62: 0 | C62: 54 | D62: 20 | F62: 200 | J62: 1.16 | M62: 0.76
D64: Corrente
B66: Escala .3 | C66: corrente | D66: counts | F66: Escala 1 | G66: corrente | H66: counts | L66: 0.98 | M66: 1 | N66: 0.84
B67: 30s | C67: 2.42e-12 | D67: 66598 | F67: 30s | G67: 2.46e-12 | H67: 22094 | L67: 0.98 | M67: 1 | N67: 0.84
C68: 1.97e-12 | D68: 56753 | G68: 1.86e-12 | H68: 17545 | L68: 1.03 | M68: 1.03 | N68: 0.84
C69: 1.28e-12 | D69: 41166 | G69: 1.5e-12 | H69: 14772 | L69: 1.04 | M69: 1.03 | N69: 0.84
C70: 8.8e-13 | D70: 31837 | G70: 1e-12 | H70: 10987 | L70: 1.01 | M70: 0.98 | N70: 0.84
B71: Fundo | C71: 1.2e-13 | D71: 14594 | F71: Fundo | G71: 1.2e-13 | H71: 4398 | L71: 0.98 | M71: 1 | N71: 0.84
L72: 1.01 | M72: 1.02 | N72: 0.84
L73: 1.02 | M73: 1.03 | N73: 0.84
C74: i (A) | D74: Counts-fundo/s | G74: i (A) | H74: Counts-fundo/s | L74: 1.04 | M74: 1 | N74: 0.84
C75: =C67-$C$71 -> 2.3e-12 | D75: =(D67-$D$71)/30 -> 1733.4667 | G75: =G67-$G$71 -> 2.34e-12 | H75: =(H67-$H$71)/30 -> 589.86667 | L75: 0.99 | M75: 0.99 | N75: 0.84
C76: =C68-$C$71 -> 1.85e-12 | D76: =(D68-$D$71)/30 -> 1405.3 | G76: =G68-$G$71 -> 1.74e-12 | H76: =(H68-$H$71)/30 -> 438.23333 | L76: 1 | M76: 1.02 | N76: 0.84
...

Sheet correcoes
D3: =input!D7 -> Sem Feixe | F3: MEDIDA | N3: Medida | O3: p corrigida
B4: =input!B8 -> tempo(ns) | C4: =input!C8 -> medida | D4: =input!D8 -> t (s) | E4: =input!E8 -> # i | F4: =input!F8 -> t (s) | G4: =input!G8 -> # i | H4: =input!H8 -> pi(mTorr) | I4: =input!I8 -> pf(mTorr) | J4: =input!J8 -> fundo | M4: n da medida | N4: Count real | O4: Torr
B5: =input!B9 -> 0 | C5: =input!C9 -> 1 | D5: =input!D9 -> 20 | E5: =input!E9 -> 8359 | F5: =input!F9 -> 200 | G5: =input!G9 -> 268328 | H5: =input!H9 -> 1.48 | I5: =input!I9 -> 1.48 | J5: =input!J9 -> 1.16 | M5: =C5 -> 1 | N5: =G5-((F5/D5)*E5) -> 184738 | O5: =(((H5+I5)/2)-J5)*0.001 -> 0.00032
B6: =input!B10 -> 0 | C6: =input!C10 -> 2 | D6: =input!D10 -> 20 | E6: =input!E10 -> 8380 | F6: =input!F10 -> 200 | G6: =input!G10 -> 339451 | H6: =input!H10 -> 1.48 | I6: =input!I10 -> 1.48 | J6: =input!J10 -> 1.16 | M6: =C6 -> 2 | N6: =G6-((F6/D6)*E6) -> 255651 | O6: =(((H6+I6)/2)-J6)*0.001 -> 0.00032
B7: =input!B11 -> 100 | C7: =input!C11 -> 3 | D7: =input!D11 -> 20 | E7: =input!E11 -> 8132 | F7: =input!F11 -> 200 | G7: =input!G11 -> 244483 | H7: =input!H11 -> 1.49 | I7: =input!I11 -> 1.49 | J7: =input!J11 -> 1.16 | M7: =C7 -> 3 | N7: =G7-((F7/D7)*E7) -> 163163 | O7: =(((H7+I7)/2)-J7)*0.001 -> 0.00033
B8: =input!B12 -> 100 | C8: =input!C12 -> 4 | D8: =input!D12 -> 20 | E8: =input!E12 -> 8118 | F8: =input!F12 -> 200 | G8: =input!G12 -> 271876 | H8: =input!H12 -> 1.49 | I8: =input!I12 -> 1.49 | J8: =input!J12 -> 1.16 | M8: =C8 -> 4 | N8: =G8-((F8/D8)*E8) -> 190696 | O8: =(((H8+I8)/2)-J8)*0.001 -> 0.00033
B9: =input!B13 -> 200 | C9: =input!C13 -> 5 | D9: =input!D13 -> 20 | E9: =input!E13 -> 8135 | F9: =input!F13 -> 200 | G9: =input!G13 -> 307177 | H9: =input!H13 -> 1.49 | I9: =input!I13 -> 1.49 | J9: =input!J13 -> 1.16 | M9: =C9 -> 5 | N9: =G9-((F9/D9)*E9) -> 225827 | O9: =(((H9+I9)/2)-J9)*0.001 -> 0.00033
B10: =input!B14 -> 200 | C10: =input!C14 -> 6 | D10: =input!D14 -> 20 | E10: =input!E14 -> 8171 | F10: =input!F14 -> 200 | G10: =input!G14 -> 253503 | H10: =input!H14 -> 1.49 | I10: =input!I14 -> 1.49 | J10: =input!J14 -> 1.16 | M10: =C10 -> 6 | N10: =G10-((F10/D10)*E10) -> 171793 | O10: =(((H10+I10)/2)-J10)*0.001 -> 0.00033
B11: =input!B15 -> 300 | C11: =input!C15 -> 7 | D11: =input!D15 -> 20 | E11: =input!E15 -> 8119 | F11: =input!F15 -> 200 | G11: =input!G15 -> 250327 | H11: =input!H15 -> 1.49 | I11: =input!I15 -> 1.49 | J11: =input!J15 -> 1.16 | M11: =C11 -> 7 | N11: =G11-((F11/D11)*E11) -> 169137 | O11: =(((H11+I11)/2)-J11)*0.001 -> 0.00033
B12: =input!B16 -> 300 | C12: =input!C16 -> 8 | D12: =input!D16 -> 20 | E12: =input!E16 -> 8135 | F12: =input!F16 -> 200 | G12: =input!G16 -> 254408 | H12: =input!H16 -> 1.49 | I12: =input!I16 -> 1.49 | J12: =input!J16 -> 1.16 | M12: =C12 -> 8 | N12: =G12-((F12/D12)*E12) -> 173058 | O12: =(((H12+I12)/2)-J12)*0.001 -> 0.00033
B13: =input!B17 -> 400 | C13: =input!C17 -> 9 | D13: =input!D17 -> 20 | E13: =input!E17 -> 8115 | F13: =input!F17 -> 200 | G13: =input!G17 -> 264086 | H13: =input!H17 -> 1.49 | I13: =input!I17 -> 1.49 | J13: =input!J17 -> 1.16 | M13: =C13 -> 9 | N13: =G13-((F13/D13)*E13) -> 182936 | O13: =(((H13+I13)/2)-J13)*0.001 -> 0.00033
B14: =input!B18 -> 400 | C14: =input!C18 -> 10 | D14: =input!D18 -> 20 | E14: =input!E18 -> 8262 | F14: =input!F18 -> 200 | G14: =input!G18 -> 255708 | H14: =input!H18 -> 1.49 | I14: =input!I18 -> 1.49 | J14: =input!J18 -> 1.16 | M14: =C14 -> 10 | N14: =G14-((F14/D14)*E14) -> 173088 | O14: =(((H14+I14)/2)-J14)*0.001 -> 0.00033
B15: =input!B19 -> 500 | C15: =input!C19 -> 11 | D15: =input!D19 -> 20 | E15: =input!E19 -> 8350 | F15: =input!F19 -> 200 | G15: =input!G19 -> 278293 | H15: =input!H19 -> 1.48 | I15: =input!I19 -> 1.48 | J15: =input!J19 -> 1.16 | M15: =C15 -> 11 | N15: =G15-((F15/D15)*E15) -> 194793 | O15: =(((H15+I15)/2)-J15)*0.001 -> 0.00032
B16: =input!B20 -> 500 | C16: =input!C20 -> 12 | D16: =input!D20 -> 20 | E16: =input!E20 -> 8269 | F16: =input!F20 -> 200 | G16: =input!G20 -> 274263 | H16: =input!H20 -> 1.48 | I16: =input!I20 -> 1.48 | J16: =input!J20 -> 1.16 | M16: =C16 -> 12 | N16: =G16-((F16/D16)*E16) -> 191573 | O16: =(((H16+I16)/2)-J16)*0.001 -> 0.00032
... B58: =input!B62 -> 0 | C58: =input!C62 -> 54 | D58: =input!D62 -> 20 | E58: =input!E62 -> 0 | F58: =input!F62 -> 200 | G58: =input!G62 -> 0 | H58: =input!H62 -> 0 | I58: =input!I62 -> 0 | J58: =input!J62 -> 1.16 | M58: =C58 -> 54 | N58: =G58-((F58/D58)*E58) -> 0 | O58: =(((H58+I58)/2)-J58)*0.001 -> -0.00116
B61: Correção da pressão | I61: Correção da corrente
E62: p_corrigida (Torr) | G62: n_total | L62: carga ( C ) | M62: Ne
E63: =O5 -> 0.00032 | F63: =C5 -> 1 | G63: =((E63*$C$66)/(kb*T))*0.000001 -> 1.0551358e+13 | K63: =C5 -> 1 | L63: =N5*alfa -> 2.4403963e-10 | M63: =L63*$J$67 -> 1.5228073e+09
E64: =O6 -> 0.00032 | F64: =C6 -> 2 | G64: =((E64*$C$66)/(kb*T))*0.000001 -> 1.0551358e+13 | I64: alfa | J64: =1/757000000000000 -> 1.321004e-15 | K64: =C6 -> 2 | L64: =N6*alfa -> 3.3771598e-10 | M64: =L64*$J$67 -> 2.1073477e+09
E65: =O7 -> 0.00033 | F65: =C7 -> 3 | G65: =((E65*$C$66)/(kb*T))*0.000001 -> 1.0881088e+13 | K65: =C7 -> 3 | L65: =N7*alfa -> 2.1553897e-10 | M65: =L65*$J$67 -> 1.3449632e+09
B66: 1 torr | C66: 133.323 | D66: Pa | E66: =O8 -> 0.00033 | F66: =C8 -> 4 | G66: =((E66*$C$66)/(kb*T))*0.000001 -> 1.0881088e+13 | K66: =C8 -> 4 | L66: =N8*alfa -> 2.5191017e-10 | M66: =L66*$J$67 -> 1.5719195e+09
E67: =O9 -> 0.00033 | F67: =C9 -> 5 | G67: =((E67*$C$66)/(kb*T))*0.000001 -> 1.0881088e+13 | I67: 1C | J67: 6.24e+18 | K67: =C9 -> 5 | L67: =N9*alfa -> 2.9831836e-10 | M67: =L67*$J$67 -> 1.8615066e+09
E68: =O10 -> 0.00033 | F68: =C10 -> 6 | G68: =((E68*$C$66)/(kb*T))*0.000001 -> 1.0881088e+13 | K68: =C10 -> 6 | L68: =N10*alfa -> 2.2693923e-10 | M68: =L68*$J$67 -> 1.4161008e+09
B69: kb | C69: 1.38e-23 | D69: J/K | E69: =O11 -> 0.00033 | F69: =C11 -> 7 | G69: =((E69*$C$66)/(kb*T))*0.000001 -> 1.0881088e+13 | K69: =C11 -> 7 | L69: =N11*alfa -> 2.2343065e-10 | M69: =L69*$J$67 -> 1.3942072e+09
B70: T | C70: 293 | D70: K | E70: =O12 -> 0.00033 | F70: =C12 -> 8 | G70: =((E70*$C$66)/(kb*T))*0.000001 -> 1.0881088e+13 | K70: =C12 -> 8 | L70: =N12*alfa -> 2.286103e-10 | M70: =L70*$J$67 -> 1.4265283e+09
E71: =O13 -> 0.00033 | F71: =C13 -> 9 | G71: =((E71*$C$66)/(kb*T))*0.000001 -> 1.0881088e+13 | K71: =C13 -> 9 | L71: =N13*alfa -> 2.4165918e-10 | M71: =L71*$J$67 -> 1.5079533e+09
E72: =O14 -> 0.00033 | F72: =C14 -> 10 | G72: =((E72*$C$66)/(kb*T))*0.000001 -> 1.0881088e+13 | K72: =C14 -> 10 | L72: =N14*alfa -> 2.2864993e-10 | M72: =L72*$J$67 -> 1.4267756e+09
B73: =kb*T -> 4.0434e-21 | E73: =O15 -> 0.00032 | F73: =C15 -> 11 | G73: =((E73*$C$66)/(kb*T))*0.000001 -> 1.0551358e+13 | K73: =C15 -> 11 | L73: =N15*alfa -> 2.5732232e-10 | M73: =L73*$J$67 -> 1.6056913e+09
E74: =O16 -> 0.00032 | F74: =C16 -> 12 | G74: =((E74*$C$66)/(kb*T))*0.000001 -> 1.0551358e+13 | K74: =C16 -> 12 | L74: =N16*alfa -> 2.5306869e-10 | M74: =L74*$J$67 -> 1.5791486e+09
E75: =O17 -> 0.00032 | F75: =C17 -> 13 | G75: =((E75*$C$66)/(kb*T))*0.000001 -> 1.0551358e+13 | K75: =C17 -> 13 | L75: =N17*alfa -> 2.9300661e-10 | M75: =L75*$J$67 -> 1.8283612e+09
E76: =O18 -> 0.00032 | F76: =C18 -> 14 | G76: =((E76*$C$66)/(kb*T))*0.000001 -> 1.0551358e+13 | K76: =C18 -> 14 | L76: =N18*alfa -> 3.0742668e-10 | M76: =L76*$J$67 -> 1.9183425e+09
E77: =O19 -> 0.000315 | F77: =C19 -> 15 | G77: =((E77*$C$66)/(kb*T))*0.000001 -> 1.0386493e+13 | K77: =C19 -> 15 | L77: =N19*alfa -> 3.3177807e-10 | M77: =L77*$J$67 -> 2.0702952e+09
E78: =O20 -> 0.000315 | F78: =C20 -> 16 | G78: =((E78*$C$66)/(kb*T))*0.000001 -> 1.0386493e+13 | K78: =C20 -> 16 | L78: =N20*alfa -> 2.7920608e-10 | M78: =L78*$J$67 -> 1.7422459e+09
E79: =O21 -> 0.00032 | F79: =C21 -> 17 | G79: =((E79*$C$66)/(kb*T))*0.000001 -> 1.0551358e+13 | K79: =C21 -> 17 | L79: =N21*alfa -> 2.6340555e-10 | M79: =L79*$J$67 -> 1.6436506e+09
E80: =O22 -> 0.00032 | F80: =C22 -> 18 | G80: =((E80*$C$66)/(kb*T))*0.000001 -> 1.0551358e+13 | K80: =C22 -> 18 | L80: =N22*alfa -> 2.4194848e-10 | M80: =L80*$J$67 -> 1.5097585e+09
E81: =O23 -> 0.000315 | F81: =C23 -> 19 | G81: =((E81*$C$66)/(kb*T))*0.000001 -> 1.0386493e+13 | K81: =C23 -> 19 | L81: =N23*alfa -> 2.4742668e-10 | M81: =L81*$J$67 -> 1.5439425e+09
E82: =O24 -> 0.00032 | F82: =C24 -> 20 | G82: =((E82*$C$66)/(kb*T))*0.000001 -> 1.0551358e+13 | K82: =C24 -> 20 | L82: =N24*alfa -> 2.5257728e-10 | M82: =L82*$J$67 -> 1.5760822e+09
E83: =O25 -> 0.000325 | F83: =C25 -> 21 | G83: =((E83*$C$66)/(kb*T))*0.000001 -> 1.0716223e+13 | K83: =C25 -> 21 | L83: =N25*alfa -> 2.1399075e-10 | M83: =L83*$J$67 -> 1.3353023e+09
E84: =O26 -> 0.000325 | F84: =C26 -> 22 | G84: =((E84*$C$66)/(kb*T))*0.000001 -> 1.0716223e+13 | K84: =C26 -> 22 | L84: =N26*alfa -> 3.0961559e-10 | M84: =L84*$J$67 -> 1.9320013e+09
E85: =O27 -> 0.000335 | F85: =C27 -> 23 | G85: =((E85*$C$66)/(kb*T))*0.000001 -> 1.1045953e+13 | K85: =C27 -> 23 | L85: =N27*alfa -> 2.7005284e-10 | M85: =L85*$J$67 -> 1.6851297e+09
...

Sheet areas
B4: áreas
B5: =correcoes!B4 -> tempo(ns) | C5: =correcoes!C4 -> medida | D5: O++ | E5: O+ | F5: O2+ | H5: =B5 -> tempo(ns) | I5: N+/N2+
B6: =correcoes!B5 -> 0 | C6: =correcoes!C5 -> 1 | E6: 43219 | F6: 102636 | H6: =B6 -> 0 | I6: =E6/F6 -> 0.42109007
B7: =correcoes!B6 -> 0 | C7: =correcoes!C6 -> 2 | E7: 59950 | F7: 141503 | H7: =B7 -> 0 | I7: =E7/F7 -> 0.42366593
B8: =correcoes!B7 -> 100 | C8: =correcoes!C7 -> 3 | E8: 35368 | F8: 92538 | H8: =B8 -> 100 | I8: =E8/F8 -> 0.38219974
B9: =correcoes!B8 -> 100 | C9: =correcoes!C8 -> 4 | E9: 42100 | F9: 109408 | H9: =B9 -> 100 | I9: =E9/F9 -> 0.38479819
B10: =correcoes!B9 -> 200 | C10: =correcoes!C9 -> 5 | E10: 45520 | F10: 127964 | H10: =B10 -> 200 | I10: =E10/F10 -> 0.35572505
B11: =correcoes!B10 -> 200 | C11: =correcoes!C10 -> 6 | E11: 35026 | F11: 99922 | H11: =B11 -> 200 | I11: =E11/F11 -> 0.35053342
B12: =correcoes!B11 -> 300 | C12: =correcoes!C11 -> 7 | E12: 31483 | F12: 97080 | H12: =B12 -> 300 | I12: =E12/F12 -> 0.32429955
B13: =correcoes!B12 -> 300 | C13: =correcoes!C12 -> 8 | E13: 32208 | F13: 99631 | H13: =B13 -> 300 | I13: =E13/F13 -> 0.32327288
B14: =correcoes!B13 -> 400 | C14: =correcoes!C13 -> 9 | E14: 31024 | F14: 103720 | H14: =B14 -> 400 | I14: =E14/F14 -> 0.299113
B15: =correcoes!B14 -> 400 | C15: =correcoes!C14 -> 10 | E15: 29594 | F15: 98803 | H15: =B15 -> 400 | I15: =E15/F15 -> 0.29952532
B16: =correcoes!B15 -> 500 | C16: =correcoes!C15 -> 11 | E16: 30372 | F16: 111683 | H16: =B16 -> 500 | I16: =E16/F16 -> 0.27194828
B17: =correcoes!B16 -> 500 | C17: =correcoes!C16 -> 12 | E17: 30068 | F17: 109255 | H17: =B17 -> 500 | I17: =E17/F17 -> 0.27520937
... B57: =correcoes!B56 -> 0 | C57: =correcoes!C56 -> 52 | E57: 81027 | F57: 193608 | H57: =B57 -> 0 | I57: =E57/F57 -> 0.4185106
B58: =correcoes!B57 -> 0 | C58: =correcoes!C57 -> 53 | H58: =B58 -> 0 | I58: =E58/F58 -> #DIV/0!
B59: =correcoes!B58 -> 0 | C59: =correcoes!C58 -> 54 | H59: =B59 -> 0 | I59: =E59/F59 -> #DIV/0!

Sheet Analise_tempo
D2: d | E2: 0.6
D8: =areas!E5 -> O+
B9: =input!B8 -> tempo(ns) | C9: =input!C8 -> medida | D9: área | E9: =correcoes!G62 -> n_total | F9: =correcoes!M62 -> Ne | G9: s exp
B10: =input!B9 -> 0 | C10: =input!C9 -> 1 | D10: =areas!E6 -> 43219 | E10: =correcoes!G63 -> 1.0551358e+13 | F10: =correcoes!M63 -> 1.5228073e+09 | G10: =D10/(E10*F10*d) -> 4.4830147e-18
B11: =input!B10 -> 0 | C11: =input!C10 -> 2 | D11: =areas!E7 -> 59950 | E11: =correcoes!G64 -> 1.0551358e+13 | F11: =correcoes!M64 -> 2.1073477e+09 | G11: =D11/(E11*F11*d) -> 4.4935894e-18 | I11: =B9 -> tempo(ns) | J11: =G9 -> s exp
B12: =input!B11 -> 100 | C12: =input!C11 -> 3 | D12: =areas!E8 -> 35368 | E12: =correcoes!G65 -> 1.0881088e+13 | F12: =correcoes!M65 -> 1.3449632e+09 | G12: =D12/(E12*F12*d) -> 4.0278802e-18 | I12: =AVERAGE(B10:B11) -> 0 | J12: =AVERAGE(G10:G11) -> 4.488302e-18 | L12: =I11 -> tempo(ns) | M12: u/u0
B13: =input!B12 -> 100 | C13: =input!C12 -> 4 | D13: =areas!E9 -> 42100 | E13: =correcoes!G66 -> 1.0881088e+13 | F13: =correcoes!M66 -> 1.5719195e+09 | G13: =D13/(E13*F13*d) -> 4.1023078e-18 | I13: =AVERAGE(B12:B13) -> 100 | J13: =AVERAGE(G12:G13) -> 4.065094e-18 | L13: =I13 -> 100 | M13: =J13/$J$12 -> 0.90570866
B14: =input!B13 -> 200 | C14: =input!C13 -> 5 | D14: =areas!E10 -> 45520 | E14: =correcoes!G67 -> 1.0881088e+13 | F14: =correcoes!M67 -> 1.8615066e+09 | G14: =D14/(E14*F14*d) -> 3.7455372e-18 | I14: =AVERAGE(B14:B15) -> 200 | J14: =AVERAGE(G14:G15) -> 3.7670427e-18 | L14: =I14 -> 200 | M14: =J14/$J$12 -> 0.8393024
B15: =input!B14 -> 200 | C15: =input!C14 -> 6 | D15: =areas!E11 -> 35026 | E15: =correcoes!G68 -> 1.0881088e+13 | F15: =correcoes!M68 -> 1.4161008e+09 | G15: =D15/(E15*F15*d) -> 3.7885481e-18 | I15: =AVERAGE(B16:B17) -> 300 | J15: =AVERAGE(G16:G17) -> 3.4585377e-18 | L15: =I15 -> 300 | M15: =J15/$J$12 -> 0.77056705
B16: =input!B15 -> 300 | C16: =input!C15 -> 7 | D16: =areas!E12 -> 31483 | E16: =correcoes!G69 -> 1.0881088e+13 | F16: =correcoes!M69 -> 1.3942072e+09 | G16: =D16/(E16*F16*d) -> 3.4587981e-18 | I16: =AVERAGE(B18:B19) -> 400 | J16: =AVERAGE(G18:G19) -> 3.1641641e-18 | L16: =I16 -> 400 | M16: =J16/$J$12 -> 0.7049802
B17: =input!B16 -> 300 | C17: =input!C16 -> 8 | D17: =areas!E13 -> 32208 | E17: =correcoes!G70 -> 1.0881088e+13 | F17: =correcoes!M70 -> 1.4265283e+09 | G17: =D17/(E17*F17*d) -> 3.4582772e-18 | I17: =AVERAGE(B20:B21) -> 500 | J17: =AVERAGE(G20:G21) -> 2.9977072e-18 | L17: =I17 -> 500 | M17: =J17/$J$20 -> 0.6504846
B18: =input!B17 -> 400 | C18: =input!C17 -> 9 | D18: =areas!E14 -> 31024 | E18: =correcoes!G71 -> 1.0881088e+13 | F18: =correcoes!M71 -> 1.5079533e+09 | G18: =D18/(E18*F18*d) -> 3.1512753e-18 | I18: =AVERAGE(B22:B23) -> 600 | J18: =AVERAGE(G22:G23) -> 2.7608722e-18 | L18: =I18 -> 600 | M18: =J18/$J$20 -> 0.59909283
B19: =input!B18 -> 400 | C19: =input!C18 -> 10 | D19: =areas!E15 -> 29594 | E19: =correcoes!G72 -> 1.0881088e+13 | F19: =correcoes!M72 -> 1.4267756e+09 | G19: =D19/(E19*F19*d) -> 3.1770528e-18 | I19: =AVERAGE(B24:B25) -> 800 | J19: =AVERAGE(G24:G25) -> 2.310627e-18 | L19: =I19 -> 800 | M19: =J19/$J$20 -> 0.50139231
B20: =input!B19 -> 500 | C20: =input!C19 -> 11 | D20: =areas!E16 -> 30372 | E20: =correcoes!G73 -> 1.0551358e+13 | F20: =correcoes!M73 -> 1.6056913e+09 | G20: =D20/(E20*F20*d) -> 2.9878015e-18 | I20: =AVERAGE(B26:B27) -> 0 | J20: =AVERAGE(G26:G27) -> 4.6084214e-18 | L20: =I20 -> 0 | M20: =J20/$J$20 -> 1
B21: =input!B20 -> 500 | C21: =input!C20 -> 12 | D21: =areas!E17 -> 30068 | E21: =correcoes!G74 -> 1.0551358e+13 | F21: =correcoes!M74 -> 1.5791486e+09 | G21: =D21/(E21*F21*d) -> 3.0076129e-18 | I21: =AVERAGE(B28:B29) -> 1000 | J21: =AVERAGE(G28:G29) -> 1.9354571e-18 | L21: =I21 -> 1000 | M21: =J21/$J$20 -> 0.41998266
B22: =input!B21 -> 600 | C22: =input!C21 -> 13 | D22: =areas!E18 -> 31917 | E22: =correcoes!G75 -> 1.0551358e+13 | F22: =correcoes!M75 -> 1.8283612e+09 | G22: =D22/(E22*F22*d) -> 2.7574044e-18 | I22: =AVERAGE(B30:B31) -> 1250 | J22: =AVERAGE(G30:G31) -> 1.5833549e-18 | L22: =I22 -> 1250 | M22: =J22/$J$20 -> 0.34357858
B23: =input!B22 -> 600 | C23: =input!C22 -> 14 | D23: =areas!E19 -> 33572 | E23: =correcoes!G76 -> 1.0551358e+13 | F23: =correcoes!M76 -> 1.9183425e+09 | G23: =D23/(E23*F23*d) -> 2.76434e-18 | I23: =AVERAGE(B32:B33) -> 1500 | J23: =AVERAGE(G32:G33) -> 1.3326276e-18 | L23: =I23 -> 1500 | M23: =J23/$J$20 -> 0.28917226
B24: =input!B23 -> 800 | C24: =input!C23 -> 15 | D24: =areas!E20 -> 29988 | E24: =correcoes!G77 -> 1.0386493e+13 | F24: =correcoes!M77 -> 2.0702952e+09 | G24: =D24/(E24*F24*d) -> 2.3243154e-18 | I24: =AVERAGE(B34:B35) -> 1750 | J24: =AVERAGE(G34:G35) -> 1.136967e-18 | L24: =I24 -> 1750 | M24: =J24/$J$20 -> 0.24671507
B25: =input!B24 -> 800 | C25: =input!C24 -> 16 | D25: =areas!E21 -> 24939 | E25: =correcoes!G78 -> 1.0386493e+13 | F25: =correcoes!M78 -> 1.7422459e+09 | G25: =D25/(E25*F25*d) -> 2.2969387e-18 | I25: =AVERAGE(B36:B37) -> 2000 | J25: =AVERAGE(G36:G37) -> 9.758916e-19 | L25: =I25 -> 2000 | M25: =J25/$J$28 -> 0.2131784
B26: =input!B25 -> 0 | C26: =input!C25 -> 17 | D26: =areas!E22 -> 47832 | E26: =correcoes!G79 -> 1.0551358e+13 | F26: =correcoes!M79 -> 1.6436506e+09 | G26: =D26/(E26*F26*d) -> 4.5967346e-18 | I26: =AVERAGE(B38:B39) -> 2250 | J26: =AVERAGE(G38:G39) -> 8.5276806e-19 | L26: =I26 -> 2250 | M26: =J26/$J$28 -> 0.18628271
B27: =input!B26 -> 0 | C27: =input!C26 -> 18 | D27: =areas!E23 -> 44159 | E27: =correcoes!G80 -> 1.0551358e+13 | F27: =correcoes!M80 -> 1.5097585e+09 | G27: =D27/(E27*F27*d) -> 4.6201081e-18 | I27: =AVERAGE(B40:B41) -> 2500 | J27: =AVERAGE(G40:G41) -> 7.7284219e-19 | L27: =I27 -> 2500 | M27: =J27/$J$28 -> 0.16882332
B28: =input!B27 -> 1000 | C28: =input!C27 -> 19 | D28: =areas!E24 -> 18734 | E28: =correcoes!G81 -> 1.0386493e+13 | F28: =correcoes!M81 -> 1.5439425e+09 | G28: =D28/(E28*F28*d) -> 1.9470595e-18 | I28: =AVERAGE(B42:B43) -> 0 | J28: =AVERAGE(G42:G43) -> 4.5778164e-18 | L28: =I28 -> 0 | M28: =J28/$J$28 -> 1
B29: =input!B28 -> 1000 | C29: =input!C28 -> 20 | D29: =areas!E25 -> 19196 | E29: =correcoes!G82 -> 1.0551358e+13 | F29: =correcoes!M82 -> 1.5760822e+09 | G29: =D29/(E29*F29*d) -> 1.9238547e-18 | I29: =AVERAGE(B44:B45) -> 3000 | J29: =AVERAGE(G44:G45) -> 6.3351126e-19 | L29: =I29 -> 3000 | M29: =J29/$J$28 -> 0.13838721
B30: =input!B29 -> 1250 | C30: =input!C29 -> 21 | D30: =areas!E26 -> 13180 | E30: =correcoes!G83 -> 1.0716223e+13 | F30: =correcoes!M83 -> 1.3353023e+09 | G30: =D30/(E30*F30*d) -> 1.5351218e-18 | I30: =AVERAGE(B46:B47) -> 3500 | J30: =AVERAGE(G46:G47) -> 5.2705188e-19 | L30: =I30 -> 3500 | M30: =J30/$J$28 -> 0.11513172
B31: =input!B30 -> 1250 | C31: =input!C30 -> 22 | D31: =areas!E27 -> 20268 | E31: =correcoes!G84 -> 1.0716223e+13 | F31: =correcoes!M84 -> 1.9320013e+09 | G31: =D31/(E31*F31*d) -> 1.631588e-18 | I31: =AVERAGE(B48:B49) -> 4000 | J31: =AVERAGE(G48:G49) -> 4.672759e-19 | L31: =I31 -> 4000 | M31: =J31/$J$28 -> 0.10207397
B32: =input!B31 -> 1500 | C32: =input!C31 -> 23 | D32: =areas!E28 -> 14851 | E32: =correcoes!G85 -> 1.1045953e+13 | F32: =correcoes!M85 -> 1.6851297e+09 | G32: =D32/(E32*F32*d) -> 1.3297437e-18 | I32: =AVERAGE(B50:B51) -> 4700 | J32: =AVERAGE(G50:G51) -> 3.9156749e-19 | L32: =I32 -> 4700 | M32: =J32/$J$28 -> 0.085535865
B33: =input!B32 -> 1500 | C33: =input!C32 -> 24 | D33: =areas!E29 -> 17526 | E33: =correcoes!G86 -> 1.1210818e+13 | F33: =correcoes!M86 -> 1.9509521e+09 | G33: =D33/(E33*F33*d) -> 1.3355116e-18 | I33: =AVERAGE(B52:B53) -> 5400 | J33: =AVERAGE(G52:G53) -> 3.3612452e-19 | L33: =I33 -> 5400 | M33: =J33/$J$28 -> 0.073424639
B34: =input!B33 -> 1750 | C34: =input!C33 -> 25 | D34: =areas!E30 -> 13756 | E34: =correcoes!G87 -> 1.1045953e+13 | F34: =correcoes!M87 -> 1.812584e+09 | G34: =D34/(E34*F34*d) -> 1.1450899e-18 | I34: =AVERAGE(B54:B55) -> 6200 | J34: =AVERAGE(G54:G55) -> 2.6350169e-19 | L34: =I34 -> 6200 | M34: =J34/$J$37 -> 0.057466364
B35: =input!B34 -> 1750 | C35: =input!C34 -> 26 | D35: =areas!E31 -> 12050 | E35: =correcoes!G88 -> 1.1210818e+13 | F35: =correcoes!M88 -> 1.5869548e+09 | G35: =D35/(E35*F35*d) -> 1.128844e-18 | I35: =AVERAGE(B56:B57) -> 7000 | J35: =AVERAGE(G56:G57) -> 2.1415532e-19 | L35: =I35 -> 7000 | M35: =J35/$J$37 -> 0.046704549
B36: =input!B35 -> 2000 | C36: =input!C35 -> 27 | D36: =areas!E32 -> 9857 | E36: =correcoes!G89 -> 1.1045953e+13 | F36: =correcoes!M89 -> 1.5574446e+09 | G36: =D36/(E36*F36*d) -> 9.5494357e-19 | I36: =AVERAGE(B58:B59) -> 8000 | J36: =AVERAGE(G58:G59) -> 1.6730128e-19 | L36: =I36 -> 8000 | M36: =J36/$J$37 -> 0.036486278
B37: =input!B36 -> 2000 | C37: =input!C36 -> 28 | D37: =areas!E33 -> 12405 | E37: =correcoes!G90 -> 1.0881088e+13 | F37: =correcoes!M90 -> 1.9061098e+09 | G37: =D37/(E37*F37*d) -> 9.9683962e-19 | I37: =AVERAGE(B60:B61) -> 0 | J37: =AVERAGE(G60:G61) -> 4.5853204e-18 | L37: =I37 -> 0 | M37: =J37/$J$37 -> 1
B38: =input!B37 -> 2250 | C38: =input!C37 -> 29 | D38: =areas!E34 -> 9322 | E38: =correcoes!G91 -> 1.1045953e+13 | F38: =correcoes!M91 -> 1.6425873e+09 | G38: =D38/(E38*F38*d) -> 8.5630054e-19
B39: =input!B38 -> 2250 | C39: =input!C38 -> 30 | D39: =areas!E35 -> 9382 | E39: =correcoes!G92 -> 1.1045953e+13 | F39: =correcoes!M92 -> 1.6669125e+09 | G39: =D39/(E39*F39*d) -> 8.4923559e-19
B40: =input!B39 -> 2500 | C40: =input!C39 -> 31 | D40: =areas!E36 -> 8519 | E40: =correcoes!G93 -> 1.0881088e+13 | F40: =correcoes!M93 -> 1.7114169e+09 | G40: =D40/(E40*F40*d) -> 7.6244628e-19
B41: =input!B40 -> 2500 | C41: =input!C40 -> 32 | D41: =areas!E37 -> 7596 | E41: =correcoes!G94 -> 1.0881088e+13 | F41: =correcoes!M94 -> 1.4854827e+09 | G41: =D41/(E41*F41*d) -> 7.8323809e-19
B42: =input!B41 -> 0 | C42: =input!C41 -> 33 | D42: =areas!E38 -> 57696 | E42: =correcoes!G95 -> 1.1210818e+13 | F42: =correcoes!M95 -> 1.8869694e+09 | G42: =D42/(E42*F42*d) -> 4.5456114e-18
B43: =input!B42 -> 0 | C43: =input!C42 -> 34 | D43: =areas!E39 -> 51736 | E43: =correcoes!G96 -> 1.1210818e+13 | F43: =correcoes!M96 -> 1.6684045e+09 | G43: =D43/(E43*F43*d) -> 4.6100214e-18
B44: =input!B43 -> 3000 | C44: =input!C43 -> 35 | D44: =areas!E40 -> 7457 | E44: =correcoes!G97 -> 1.0716223e+13 | F44: =correcoes!M97 -> 1.838393e+09 | G44: =D44/(E44*F44*d) -> 6.3085972e-19
B45: =input!B44 -> 3000 | C45: =input!C44 -> 36 | D45: =areas!E41 -> 7805 | E45: =correcoes!G98 -> 1.0551358e+13 | F45: =correcoes!M98 -> 1.937961e+09 | G45: =D45/(E45*F45*d) -> 6.3616281e-19
B46: =input!B45 -> 3500 | C46: =input!C45 -> 37 | D46: =areas!E42 -> 6337 | E46: =correcoes!G99 -> 1.0551358e+13 | F46: =correcoes!M99 -> 1.8935968e+09 | G46: =D46/(E46*F46*d) -> 5.2861148e-19
...

Sheet Plan1
